InvalidRequestError
sqlalchemy.exc.InvalidRequestError: When initializing mapper Mapper[Evidence(evidence)], expression 'DeviceAcquisition' failed to locate a name ('DeviceAcquisition'). If this is a class name, consider adding this relationship() to the <class 'models.Evidence'> class after both dependent classes have been defined.

Traceback (most recent call last)
File "/home/runner/workspace/.pythonlibs/lib/python3.11/site-packages/sqlalchemy/orm/clsregistry.py", line 516, in _resolve_name
rval = d[token]
       ^^^^^^^^
File "/home/runner/workspace/.pythonlibs/lib/python3.11/site-packages/sqlalchemy/util/_collections.py", line 345, in __missing__
self[key] = val = self.creator(key)
                  ^^^^^^^^^^^^^^^^^
File "/home/runner/workspace/.pythonlibs/lib/python3.11/site-packages/sqlalchemy/orm/clsregistry.py", line 484, in _access_cls
return self.fallback[key]
       ^^^^^^^^^^^^^^^^^^
The above exception was the direct cause of the following exception:
File "/home/runner/workspace/.pythonlibs/lib/python3.11/site-packages/flask/app.py", line 1536, in __call__
return self.wsgi_app(environ, start_response)
       ^^^^^^^^^^^^^^^^^^^^^^^^^^^^^^^^^^^^^^
File "/home/runner/workspace/.pythonlibs/lib/python3.11/site-packages/flask/app.py", line 1514, in wsgi_app
response = self.handle_exception(e)
           ^^^^^^^^^^^^^^^^^^^^^^^^
File "/home/runner/workspace/.pythonlibs/lib/python3.11/site-packages/flask/app.py", line 1511, in wsgi_app
response = self.full_dispatch_request()
           ^^^^^^^^^^^^^^^^^^^^^^^^^^^^
File "/home/runner/workspace/.pythonlibs/lib/python3.11/site-packages/flask/app.py", line 919, in full_dispatch_request
rv = self.handle_user_exception(e)
     ^^^^^^^^^^^^^^^^^^^^^^^^^^^^^
File "/home/runner/workspace/.pythonlibs/lib/python3.11/site-packages/flask/app.py", line 917, in full_dispatch_request
rv = self.dispatch_request()
     ^^^^^^^^^^^^^^^^^^^^^^^
File "/home/runner/workspace/.pythonlibs/lib/python3.11/site-packages/flask/app.py", line 902, in dispatch_request
return self.ensure_sync(self.view_functions[rule.endpoint])(**view_args)  # type: ignore[no-any-return]
       ^^^^^^^^^^^^^^^^^^^^^^^^^^^^^^^^^^^^^^^^^^^^^^^^^^^^^^^^^^^^^^^^^
File "/home/runner/workspace/app.py", line 66, in analyze
evidence = Evidence(
           
File "<string>", line 4, in __init__
File "/home/runner/workspace/.pythonlibs/lib/python3.11/site-packages/sqlalchemy/orm/state.py", line 566, in _initialize_instance
manager.dispatch.init(self, args, kwargs)
^^^^^^^^^^^^^^^^^^^^^^^^^^^^^^^^^^^^^^^^^
File "/home/runner/workspace/.pythonlibs/lib/python3.11/site-packages/sqlalchemy/event/attr.py", line 497, in __call__
fn(*args, **kw)
^^^^^^^^^^^^^^^
File "/home/runner/workspace/.pythonlibs/lib/python3.11/site-packages/sqlalchemy/orm/mapper.py", line 4405, in _event_on_init
instrumenting_mapper._check_configure()
^^^^^^^^^^^^^^^^^^^^^^^^^^^^^^^^^^^^^^^
File "/home/runner/workspace/.pythonlibs/lib/python3.11/site-packages/sqlalchemy/orm/mapper.py", line 2401, in _check_configure
_configure_registries({self.registry}, cascade=True)
^^^^^^^^^^^^^^^^^^^^^^^^^^^^^^^^^^^^^^^^^^^^^^^^^^^^
File "/home/runner/workspace/.pythonlibs/lib/python3.11/site-packages/sqlalchemy/orm/mapper.py", line 4213, in _configure_registries
_do_configure_registries(registries, cascade)
^^^^^^^^^^^^^^^^^^^^^^^^^^^^^^^^^^^^^^^^^^^^^
File "/home/runner/workspace/.pythonlibs/lib/python3.11/site-packages/sqlalchemy/orm/mapper.py", line 4254, in _do_configure_registries
mapper._post_configure_properties()
^^^^^^^^^^^^^^^^^^^^^^^^^^^^^^^^^^^
File "/home/runner/workspace/.pythonlibs/lib/python3.11/site-packages/sqlalchemy/orm/mapper.py", line 2418, in _post_configure_properties
prop.init()
^^^^^^^^^^^
File "/home/runner/workspace/.pythonlibs/lib/python3.11/site-packages/sqlalchemy/orm/interfaces.py", line 589, in init
self.do_init()
^^^^^^^^^^^^^^
File "/home/runner/workspace/.pythonlibs/lib/python3.11/site-packages/sqlalchemy/orm/relationships.py", line 1656, in do_init
self._setup_entity()
^^^^^^^^^^^^^^^^^^^^
File "/home/runner/workspace/.pythonlibs/lib/python3.11/site-packages/sqlalchemy/orm/relationships.py", line 1868, in _setup_entity
self._clsregistry_resolve_name(argument)(),
^^^^^^^^^^^^^^^^^^^^^^^^^^^^^^^^^^^^^^^^^^
File "/home/runner/workspace/.pythonlibs/lib/python3.11/site-packages/sqlalchemy/orm/clsregistry.py", line 520, in _resolve_name
self._raise_for_name(name, err)
^^^^^^^^^^^^^^^^^^^^^^^^^^^^^^^
File "/home/runner/workspace/.pythonlibs/lib/python3.11/site-packages/sqlalchemy/orm/clsregistry.py", line 501, in _raise_for_name
raise exc.InvalidRequestError(
^^^^^^^^^^
sqlalchemy.exc.InvalidRequestError: When initializing mapper Mapper[Evidence(evidence)], expression 'DeviceAcquisition' failed to locate a name ('DeviceAcquisition'). If this is a class name, consider adding this relationship() to the <class 'models.Evidence'> class after both dependent classes have been defined.
The debugger caught an exception in your WSGI application. You can now look at the traceback which led to the error.
To switch between the interactive traceback and the plaintext one, you can click on the "Traceback" headline. From the text traceback you can also create a paste of it.

Brought to you by DON'T PANIC, your friendly Werkzeug powered traceback interpreter.